Workbook

Sheet general
A1: Date | B1: dia | C1: mes | D1: ano | E1: montoSpei | F1: montoCodi | G1: tc
A2: 30/09/2019 | B2: 30 | C2: 9 | D2: 2019 | E2: 591819872132 | F2: 187009 | G2: 19.6808
A3: 43475 | B3: 1 | C3: 10 | D3: 2019 | E3: 399300877736 | F3: 311813 | G3: 19.7345
A4: 43506 | B4: 2 | C4: 10 | D4: 2019 | E4: 347345747950 | F4: 360606 | G4: 19.7792
A5: 43534 | B5: 3 | C5: 10 | D5: 2019 | E5: 355588329503 | F5: 399780 | G5: 19.7985
A6: 43565 | B6: 4 | C6: 10 | D6: 2019 | E6: 375419478809 | F6: 398796 | G6: 19.7368
A7: 43595 | B7: 5 | C7: 10 | D7: 2019 | E7: 3023572523 | F7: 345316 | G7: N/E
A8: 43626 | B8: 6 | C8: 10 | D8: 2019 | E8: 919151358 | F8: 163872 | G8: N/E
A9: 43656 | B9: 7 | C9: 10 | D9: 2019 | E9: 386172005337 | F9: 624991 | G9: 19.5255
A10: 43687 | B10: 8 | C10: 10 | D10: 2019 | E10: 320907997801 | F10: 527727 | G10: 19.5522
A11: 43718 | B11: 9 | C11: 10 | D11: 2019 | E11: 320985979167 | F11: 605193 | G11: 19.584
A12: 43748 | B12: 10 | C12: 10 | D12: 2019 | E12: 385168005726 | F12: 577209 | G12: 19.5689
A13: 43779 | B13: 11 | C13: 10 | D13: 2019 | E13: 397588748875 | F13: 464555 | G13: 19.4764
A14: 43809 | B14: 12 | C14: 10 | D14: 2019 | E14: 3034973947 | F14: 563216 | G14: N/E
A15: 13/10/2019 | B15: 13 | C15: 10 | D15: 2019 | E15: 972067233 | F15: 243721 | G15: N/E
A16: 14/10/2019 | B16: 14 | C16: 10 | D16: 2019 | E16: 312316259731 | F16: 838965 | G16: 19.3217
A17: 15/10/2019 | B17: 15 | C17: 10 | D17: 2019 | E17: 397247596619 | F17: 1069213 | G17: 19.2652
A18: 16/10/2019 | B18: 16 | C18: 10 | D18: 2019 | E18: 348903833539 | F18: 859948 | G18: 19.252
A19: 17/10/2019 | B19: 17 | C19: 10 | D19: 2019 | E19: 400746336663 | F19: 775163 | G19: 19.2135
A20: 18/10/2019 | B20: 18 | C20: 10 | D20: 2019 | E20: 383230376744 | F20: 743314 | G20: 19.1602
A21: 19/10/2019 | B21: 19 | C21: 10 | D21: 2019 | E21: 2964290713 | F21: 333801 | G21: N/E
A22: 20/10/2019 | B22: 20 | C22: 10 | D22: 2019 | E22: 968300471 | F22: 275351 | G22: N/E
A23: 21/10/2019 | B23: 21 | C23: 10 | D23: 2019 | E23: 399801438681 | F23: 535767 | G23: 19.1492
A24: 22/10/2019 | B24: 22 | C24: 10 | D24: 2019 | E24: 310478325702 | F24: 967330 | G24: 19.1422
A25: 23/10/2019 | B25: 23 | C25: 10 | D25: 2019 | E25: 317438329365 | F25: 503909 | G25: 19.105
A26: 24/10/2019 | B26: 24 | C26: 10 | D26: 2019 | E26: 352781604649 | F26: 745018 | G26: 19.1258
A27: 25/10/2019 | B27: 25 | C27: 10 | D27: 2019 | E27: 378225617243 | F27: 722181 | G27: 19.0878
A28: 26/10/2019 | B28: 26 | C28: 10 | D28: 2019 | E28: 3038682779 | F28: 417800 | G28: N/E
A29: 27/10/2019 | B29: 27 | C29: 10 | D29: 2019 | E29: 966418275 | F29: 245675 | G29: N/E
A30: 28/10/2019 | B30: 28 | C30: 10 | D30: 2019 | E30: 384931004391 | F30: 623474 | G30: 19.082
A31: 29/10/2019 | B31: 29 | C31: 10 | D31: 2019 | E31: 367933216674 | F31: 797234 | G31: 19.0543
A32: 30/10/2019 | B32: 30 | C32: 10 | D32: 2019 | E32: 414735485597 | F32: 1465232 | G32: 19.1167
A33: 31/10/2019 | B33: 31 | C33: 10 | D33: 2019 | E33: 536527843702 | F33: 1545313 | G33: 19.1643
A34: 43476 | B34: 1 | C34: 11 | D34: 2019 | E34: 387304180613 | F34: 1478850 | G34: 19.1948
A35: 43507 | B35: 2 | C35: 11 | D35: 2019 | E35: 2764382707 | F35: 565142 | G35: N/E
A36: 43535 | B36: 3 | C36: 11 | D36: 2019 | E36: 1249554134 | F36: 576343 | G36: N/E
A37: 43566 | B37: 4 | C37: 11 | D37: 2019 | E37: 365680550500 | F37: 1269475 | G37: 19.1058
A38: 43596 | B38: 5 | C38: 11 | D38: 2019 | E38: 323215846220 | F38: 1110812 | G38: 19.1525
A39: 43627 | B39: 6 | C39: 11 | D39: 2019 | E39: 319855067578 | F39: 1295271 | G39: 19.2125
A40: 43657 | B40: 7 | C40: 11 | D40: 2019 | E40: 387888182173 | F40: 1246404 | G40: 19.1953
...

Sheet general_spid
A1: Date | B1: dia | C1: mes | D1: ano | E1: montoSpei | F1: montoCodi | G1: tc
A2: 30/09/2019 | B2: 30 | C2: 9 | D2: 2019 | E2: 591819872132 | F2: 187009 | G2: 19.6808
A3: 43475 | B3: 1 | C3: 10 | D3: 2019 | E3: 399300877736 | F3: 311813 | G3: 19.7345
A4: 43506 | B4: 2 | C4: 10 | D4: 2019 | E4: 347345747950 | F4: 360606 | G4: 19.7792
A5: 43534 | B5: 3 | C5: 10 | D5: 2019 | E5: 355588329503 | F5: 399780 | G5: 19.7985
A6: 43565 | B6: 4 | C6: 10 | D6: 2019 | E6: 375419478809 | F6: 398796 | G6: 19.7368
A7: 43656 | B7: 7 | C7: 10 | D7: 2019 | E7: 386172005337 | F7: 624991 | G7: 19.5255
A8: 43687 | B8: 8 | C8: 10 | D8: 2019 | E8: 320907997801 | F8: 527727 | G8: 19.5522
A9: 43718 | B9: 9 | C9: 10 | D9: 2019 | E9: 320985979167 | F9: 605193 | G9: 19.584
A10: 43748 | B10: 10 | C10: 10 | D10: 2019 | E10: 385168005726 | F10: 577209 | G10: 19.5689
A11: 43779 | B11: 11 | C11: 10 | D11: 2019 | E11: 397588748875 | F11: 464555 | G11: 19.4764
A12: 14/10/2019 | B12: 14 | C12: 10 | D12: 2019 | E12: 312316259731 | F12: 838965 | G12: 19.3217
A13: 15/10/2019 | B13: 15 | C13: 10 | D13: 2019 | E13: 397247596619 | F13: 1069213 | G13: 19.2652
A14: 16/10/2019 | B14: 16 | C14: 10 | D14: 2019 | E14: 348903833539 | F14: 859948 | G14: 19.252
A15: 17/10/2019 | B15: 17 | C15: 10 | D15: 2019 | E15: 400746336663 | F15: 775163 | G15: 19.2135
A16: 18/10/2019 | B16: 18 | C16: 10 | D16: 2019 | E16: 383230376744 | F16: 743314 | G16: 19.1602
A17: 21/10/2019 | B17: 21 | C17: 10 | D17: 2019 | E17: 399801438681 | F17: 535767 | G17: 19.1492
A18: 22/10/2019 | B18: 22 | C18: 10 | D18: 2019 | E18: 310478325702 | F18: 967330 | G18: 19.1422
A19: 23/10/2019 | B19: 23 | C19: 10 | D19: 2019 | E19: 317438329365 | F19: 503909 | G19: 19.105
A20: 24/10/2019 | B20: 24 | C20: 10 | D20: 2019 | E20: 352781604649 | F20: 745018 | G20: 19.1258
A21: 25/10/2019 | B21: 25 | C21: 10 | D21: 2019 | E21: 378225617243 | F21: 722181 | G21: 19.0878
A22: 28/10/2019 | B22: 28 | C22: 10 | D22: 2019 | E22: 384931004391 | F22: 623474 | G22: 19.082
A23: 29/10/2019 | B23: 29 | C23: 10 | D23: 2019 | E23: 367933216674 | F23: 797234 | G23: 19.0543
... A25: 31/10/2019 | B25: 31 | C25: 10 | D25: 2019 | E25: 536527843702 | F25: 1545313 | G25: 19.1643
A26: 43476 | B26: 1 | C26: 11 | D26: 2019 | E26: 387304180613 | F26: 1478850 | G26: 19.1948
A27: 43566 | B27: 4 | C27: 11 | D27: 2019 | E27: 365680550500 | F27: 1269475 | G27: 19.1058
A28: 43596 | B28: 5 | C28: 11 | D28: 2019 | E28: 323215846220 | F28: 1110812 | G28: 19.1525
A29: 43627 | B29: 6 | C29: 11 | D29: 2019 | E29: 319855067578 | F29: 1295271 | G29: 19.2125
A30: 43657 | B30: 7 | C30: 11 | D30: 2019 | E30: 387888182173 | F30: 1246404 | G30: 19.1953
A31: 43688 | B31: 8 | C31: 11 | D31: 2019 | E31: 369354998037 | F31: 1268812 | G31: 19.1327
A32: 43780 | B32: 11 | C32: 11 | D32: 2019 | E32: 322586212312 | F32: 1348930 | G32: 19.1068
A33: 43810 | B33: 12 | C33: 11 | D33: 2019 | E33: 326005583049 | F33: 1341054 | G33: 19.109
A34: 13/11/2019 | B34: 13 | C34: 11 | D34: 2019 | E34: 371382745625 | F34: 1390373 | G34: 19.2178
A35: 14/11/2019 | B35: 14 | C35: 11 | D35: 2019 | E35: 438240703549 | F35: 2324687 | G35: 19.4543
A36: 15/11/2019 | B36: 15 | C36: 11 | D36: 2019 | E36: 451762993615 | F36: 1680075 | G36: 19.4228
A37: 19/11/2019 | B37: 19 | C37: 11 | D37: 2019 | E37: 539994389812 | F37: 2068354 | G37: 19.2063
A38: 20/11/2019 | B38: 20 | C38: 11 | D38: 2019 | E38: 405923270434 | F38: 1463983 | G38: 19.3687
A39: 21/11/2019 | B39: 21 | C39: 11 | D39: 2019 | E39: 421907816962 | F39: 1137560 | G39: 19.48
A40: 22/11/2019 | B40: 22 | C40: 11 | D40: 2019 | E40: 412298222053 | F40: 1192750 | G40: 19.4138
A41: 25/11/2019 | B41: 25 | C41: 11 | D41: 2019 | E41: 391349832172 | F41: 1025630 | G41: 19.3987
...

Sheet spidPromedio
A1: Date | B1: dia | C1: mes | D1: ano | E1: montoSpid | F1: montoSpei | G1: montoCodi | H1: tc
A2: 43474 | B2: 1 | C2: 9 | D2: 2019 | E2: 19003.2 | F2: =SUMIFS(general_spid!$E:$E,general_spid!$C:$C,C2,general_spid!$D:$D,D2) -> 591819872132 | G2: =SUMIFS(general_spid!$F:$F,general_spid!$C:$C,C2,general_spid!$D:$D,D2) -> 187009 | H2: =AVERAGEIFS(general_spid!$G:$G,general_spid!$C:$C,C2,general_spid!$D:$D,D2) -> 19.6808
A3: 43475 | B3: 1 | C3: 10 | D3: 2019 | E3: 19127.1 | F3: =SUMIFS(general_spid!$E:$E,general_spid!$C:$C,C3,general_spid!$D:$D,D3) -> 8593774440204 | G3: =SUMIFS(general_spid!$F:$F,general_spid!$C:$C,C3,general_spid!$D:$D,D3) -> 16462731 | H3: =AVERAGEIFS(general_spid!$G:$G,general_spid!$C:$C,C3,general_spid!$D:$D,D3) -> 19.347648
A4: 43476 | B4: 1 | C4: 11 | D4: 2019 | E4: 17797.8 | F4: =SUMIFS(general_spid!$E:$E,general_spid!$C:$C,C4,general_spid!$D:$D,D4) -> 8008363248854 | G4: =SUMIFS(general_spid!$F:$F,general_spid!$C:$C,C4,general_spid!$D:$D,D4) -> 28662686 | H4: =AVERAGEIFS(general_spid!$G:$G,general_spid!$C:$C,C4,general_spid!$D:$D,D4) -> 19.315455
A5: 43477 | B5: 1 | C5: 12 | D5: 2019 | E5: 20995.6 | F5: =SUMIFS(general_spid!$E:$E,general_spid!$C:$C,C5,general_spid!$D:$D,D5) -> 9415216981494 | G5: =SUMIFS(general_spid!$F:$F,general_spid!$C:$C,C5,general_spid!$D:$D,D5) -> 30189382 | H5: =AVERAGEIFS(general_spid!$G:$G,general_spid!$C:$C,C5,general_spid!$D:$D,D5) -> 19.140635
A6: 43831 | B6: 1 | C6: 1 | D6: 2020 | E6: 18610.6 | F6: =SUMIFS(general_spid!$E:$E,general_spid!$C:$C,C6,general_spid!$D:$D,D6) -> 8563080396589 | G6: =SUMIFS(general_spid!$F:$F,general_spid!$C:$C,C6,general_spid!$D:$D,D6) -> 29040271 | H6: =AVERAGEIFS(general_spid!$G:$G,general_spid!$C:$C,C6,general_spid!$D:$D,D6) -> 18.802018
A7: 43832 | B7: 1 | C7: 2 | D7: 2020 | E7: 16769.2 | F7: =SUMIFS(general_spid!$E:$E,general_spid!$C:$C,C7,general_spid!$D:$D,D7) -> 7461715858905 | G7: =SUMIFS(general_spid!$F:$F,general_spid!$C:$C,C7,general_spid!$D:$D,D7) -> 29920832 | H7: =AVERAGEIFS(general_spid!$G:$G,general_spid!$C:$C,C7,general_spid!$D:$D,D7) -> 18.798647
A8: 43833 | B8: 1 | C8: 3 | D8: 2020 | E8: 20382.6 | F8: =SUMIFS(general_spid!$E:$E,general_spid!$C:$C,C8,general_spid!$D:$D,D8) -> 9822058167944 | G8: =SUMIFS(general_spid!$F:$F,general_spid!$C:$C,C8,general_spid!$D:$D,D8) -> 46617113 | H8: =AVERAGEIFS(general_spid!$G:$G,general_spid!$C:$C,C8,general_spid!$D:$D,D8) -> 22.201795
A9: 43834 | B9: 1 | C9: 4 | D9: 2020 | E9: 20041 | F9: =SUMIFS(general_spid!$E:$E,general_spid!$C:$C,C9,general_spid!$D:$D,D9) -> 8636332018296 | G9: =SUMIFS(general_spid!$F:$F,general_spid!$C:$C,C9,general_spid!$D:$D,D9) -> 44714059 | H9: =AVERAGEIFS(general_spid!$G:$G,general_spid!$C:$C,C9,general_spid!$D:$D,D9) -> 24.24366
A10: 43835 | B10: 1 | C10: 5 | D10: 2020 | E10: 18385.6 | F10: =SUMIFS(general_spid!$E:$E,general_spid!$C:$C,C10,general_spid!$D:$D,D10) -> 7739580224334 | G10: =SUMIFS(general_spid!$F:$F,general_spid!$C:$C,C10,general_spid!$D:$D,D10) -> 60313113 | H10: =AVERAGEIFS(general_spid!$G:$G,general_spid!$C:$C,C10,general_spid!$D:$D,D10) -> 23.510545
A11: 43836 | B11: 1 | C11: 6 | D11: 2020 | E11: 14691.6 | F11: =SUMIFS(general_spid!$E:$E,general_spid!$C:$C,C11,general_spid!$D:$D,D11) -> 8477671826834 | G11: =SUMIFS(general_spid!$F:$F,general_spid!$C:$C,C11,general_spid!$D:$D,D11) -> 75136803 | H11: =AVERAGEIFS(general_spid!$G:$G,general_spid!$C:$C,C11,general_spid!$D:$D,D11) -> 22.257527
A12: 43837 | B12: 1 | C12: 7 | D12: 2020 | E12: 16613.5 | F12: =SUMIFS(general_spid!$E:$E,general_spid!$C:$C,C12,general_spid!$D:$D,D12) -> 8807530512260 | G12: =SUMIFS(general_spid!$F:$F,general_spid!$C:$C,C12,general_spid!$D:$D,D12) -> 95204664 | H12: =AVERAGEIFS(general_spid!$G:$G,general_spid!$C:$C,C12,general_spid!$D:$D,D12) -> 22.441896
A13: 43838 | B13: 1 | C13: 8 | D13: 2020 | E13: 15094.6 | F13: =SUMIFS(general_spid!$E:$E,general_spid!$C:$C,C13,general_spid!$D:$D,D13) -> 8414485492016 | G13: =SUMIFS(general_spid!$F:$F,general_spid!$C:$C,C13,general_spid!$D:$D,D13) -> 82753175 | H13: =AVERAGEIFS(general_spid!$G:$G,general_spid!$C:$C,C13,general_spid!$D:$D,D13) -> 22.222076
... A73: 45665 | B73: 1 | C73: 8 | D73: 2025 | E73: 37835.6 | F73: =SUMIFS(general_spid!$E:$E,general_spid!$C:$C,C73,general_spid!$D:$D,D73) -> 14256759408683 | G73: =SUMIFS(general_spid!$F:$F,general_spid!$C:$C,C73,general_spid!$D:$D,D73) -> 260739612 | H73: =AVERAGEIFS(general_spid!$G:$G,general_spid!$C:$C,C73,general_spid!$D:$D,D73) -> 18.713581

Sheet spidMediana
A1: Date | B1: dia | C1: mes | D1: ano | E1: montoSpid | F1: montoSpei | G1: montoCodi | H1: tc
A2: 43474 | B2: 1 | C2: 9 | D2: 2019 | E2: 19003.2 | F2: =SUMIFS(general_spid!$E:$E,general_spid!$C:$C,C2,general_spid!$D:$D,D2) -> 591819872132 | G2: =SUMIFS(general_spid!$F:$F,general_spid!$C:$C,C2,general_spid!$D:$D,D2) -> 187009 | H2: {=MEDIAN(_xlfn._xlws.FILTER(general_spid!$G:$G,(general_spid!$C:$C=C2)*(general_spid!$D:$D=D2)))} -> 19.6808
A3: 43475 | B3: 1 | C3: 10 | D3: 2019 | E3: 19127.1 | F3: =SUMIFS(general_spid!$E:$E,general_spid!$C:$C,C3,general_spid!$D:$D,D3) -> 8593774440204 | G3: =SUMIFS(general_spid!$F:$F,general_spid!$C:$C,C3,general_spid!$D:$D,D3) -> 16462731 | H3: {=MEDIAN(_xlfn._xlws.FILTER(general_spid!$G:$G,(general_spid!$C:$C=C3)*(general_spid!$D:$D=D3)))} -> 19.252
A4: 43476 | B4: 1 | C4: 11 | D4: 2019 | E4: 17797.8 | F4: =SUMIFS(general_spid!$E:$E,general_spid!$C:$C,C4,general_spid!$D:$D,D4) -> 8008363248854 | G4: =SUMIFS(general_spid!$F:$F,general_spid!$C:$C,C4,general_spid!$D:$D,D4) -> 28662686 | H4: {=MEDIAN(_xlfn._xlws.FILTER(general_spid!$G:$G,(general_spid!$C:$C=C4)*(general_spid!$D:$D=D4)))} -> 19.29325
A5: 43477 | B5: 1 | C5: 12 | D5: 2019 | E5: 20995.6 | F5: =SUMIFS(general_spid!$E:$E,general_spid!$C:$C,C5,general_spid!$D:$D,D5) -> 9415216981494 | G5: =SUMIFS(general_spid!$F:$F,general_spid!$C:$C,C5,general_spid!$D:$D,D5) -> 30189382 | H5: {=MEDIAN(_xlfn._xlws.FILTER(general_spid!$G:$G,(general_spid!$C:$C=C5)*(general_spid!$D:$D=D5)))} -> 19.00785
A6: 43831 | B6: 1 | C6: 1 | D6: 2020 | E6: 18610.6 | F6: =SUMIFS(general_spid!$E:$E,general_spid!$C:$C,C6,general_spid!$D:$D,D6) -> 8563080396589 | G6: =SUMIFS(general_spid!$F:$F,general_spid!$C:$C,C6,general_spid!$D:$D,D6) -> 29040271 | H6: {=MEDIAN(_xlfn._xlws.FILTER(general_spid!$G:$G,(general_spid!$C:$C=C6)*(general_spid!$D:$D=D6)))} -> 18.80495
A7: 43832 | B7: 1 | C7: 2 | D7: 2020 | E7: 16769.2 | F7: =SUMIFS(general_spid!$E:$E,general_spid!$C:$C,C7,general_spid!$D:$D,D7) -> 7461715858905 | G7: =SUMIFS(general_spid!$F:$F,general_spid!$C:$C,C7,general_spid!$D:$D,D7) -> 29920832 | H7: {=MEDIAN(_xlfn._xlws.FILTER(general_spid!$G:$G,(general_spid!$C:$C=C7)*(general_spid!$D:$D=D7)))} -> 18.6797
A8: 43833 | B8: 1 | C8: 3 | D8: 2020 | E8: 20382.6 | F8: =SUMIFS(general_spid!$E:$E,general_spid!$C:$C,C8,general_spid!$D:$D,D8) -> 9822058167944 | G8: =SUMIFS(general_spid!$F:$F,general_spid!$C:$C,C8,general_spid!$D:$D,D8) -> 46617113 | H8: {=MEDIAN(_xlfn._xlws.FILTER(general_spid!$G:$G,(general_spid!$C:$C=C8)*(general_spid!$D:$D=D8)))} -> 22.1518
A9: 43834 | B9: 1 | C9: 4 | D9: 2020 | E9: 20041 | F9: =SUMIFS(general_spid!$E:$E,general_spid!$C:$C,C9,general_spid!$D:$D,D9) -> 8636332018296 | G9: =SUMIFS(general_spid!$F:$F,general_spid!$C:$C,C9,general_spid!$D:$D,D9) -> 44714059 | H9: {=MEDIAN(_xlfn._xlws.FILTER(general_spid!$G:$G,(general_spid!$C:$C=C9)*(general_spid!$D:$D=D9)))} -> 24.16265
A10: 43835 | B10: 1 | C10: 5 | D10: 2020 | E10: 18385.6 | F10: =SUMIFS(general_spid!$E:$E,general_spid!$C:$C,C10,general_spid!$D:$D,D10) -> 7739580224334 | G10: =SUMIFS(general_spid!$F:$F,general_spid!$C:$C,C10,general_spid!$D:$D,D10) -> 60313113 | H10: {=MEDIAN(_xlfn._xlws.FILTER(general_spid!$G:$G,(general_spid!$C:$C=C10)*(general_spid!$D:$D=D10)))} -> 23.7574
A11: 43836 | B11: 1 | C11: 6 | D11: 2020 | E11: 14691.6 | F11: =SUMIFS(general_spid!$E:$E,general_spid!$C:$C,C11,general_spid!$D:$D,D11) -> 8477671826834 | G11: =SUMIFS(general_spid!$F:$F,general_spid!$C:$C,C11,general_spid!$D:$D,D11) -> 75136803 | H11: {=MEDIAN(_xlfn._xlws.FILTER(general_spid!$G:$G,(general_spid!$C:$C=C11)*(general_spid!$D:$D=D11)))} -> 22.3065
A12: 43837 | B12: 1 | C12: 7 | D12: 2020 | E12: 16613.5 | F12: =SUMIFS(general_spid!$E:$E,general_spid!$C:$C,C12,general_spid!$D:$D,D12) -> 8807530512260 | G12: =SUMIFS(general_spid!$F:$F,general_spid!$C:$C,C12,general_spid!$D:$D,D12) -> 95204664 | H12: {=MEDIAN(_xlfn._xlws.FILTER(general_spid!$G:$G,(general_spid!$C:$C=C12)*(general_spid!$D:$D=D12)))} -> 22.4147
A13: 43838 | B13: 1 | C13: 8 | D13: 2020 | E13: 15094.6 | F13: =SUMIFS(general_spid!$E:$E,general_spid!$C:$C,C13,general_spid!$D:$D,D13) -> 8414485492016 | G13: =SUMIFS(general_spid!$F:$F,general_spid!$C:$C,C13,general_spid!$D:$D,D13) -> 82753175 | H13: {=MEDIAN(_xlfn._xlws.FILTER(general_spid!$G:$G,(general_spid!$C:$C=C13)*(general_spid!$D:$D=D13)))} -> 22.176
... A73: 45665 | B73: 1 | C73: 8 | D73: 2025 | E73: 37835.6 | F73: =SUMIFS(general_spid!$E:$E,general_spid!$C:$C,C73,general_spid!$D:$D,D73) -> 14256759408683 | G73: =SUMIFS(general_spid!$F:$F,general_spid!$C:$C,C73,general_spid!$D:$D,D73) -> 260739612 | H73: {=MEDIAN(_xlfn._xlws.FILTER(general_spid!$G:$G,(general_spid!$C:$C=C73)*(general_spid!$D:$D=D73)))} -> 18.6912
